Workbook

Sheet Market indicators
B2: Market indicators for the outlook
B3: Values in % unless stated. Blue = hardcoded from source; black = formula. "n/a" = not retrieved, take it from the FRED chart.
B5: Indicator | C5: Source / series | D5: Units | E5: Latest date | F5: Latest | G5: 1Y ago date | H5: 1Y ago | I5: Change (bp) | J5: Supports in the portfolio
B6: Inflation
B7: 10Y breakeven inflation | C7: FRED T10YIE | D7: % | E7: 46304 | F7: 2.33 | G7: n/a | H7: n/a | I7: =IF(ISNUMBER(H7),(F7-H7)*100,"n/a") -> n/a | J7: Gold, commodities, TIPS: inflation priced vs CPI consensus (ECFC)
B8: 5Y breakeven inflation | C8: FRED T5YIE | D8: % | E8: 46304 | F8: 2.34 | G8: n/a | H8: n/a | I8: =IF(ISNUMBER(H8),(F8-H8)*100,"n/a") -> n/a | J8: Same, closer to the ECFC horizon
B9: 10Y real yield (TIPS) | C9: FRED DFII10 | D9: % | E9: 46303 | F9: 2.87 | G9: n/a | H9: n/a | I9: =IF(ISNUMBER(H9),(F9-H9)*100,"n/a") -> n/a | J9: Gold (high real yields weigh on gold), TIPS
B10: Rates
B11: 2Y Treasury yield | C11: US Treasury par yield curve | D11: % | E11: 46304 | F11: 4.8 | G11: 45939 | H11: 3.6 | I11: =IF(ISNUMBER(H11),(F11-H11)*100,"n/a") -> 120 | J11: Front end: Fed hikes priced (with WIRP)
B12: 10Y Treasury yield | C12: US Treasury par yield curve | D12: % | E12: 46304 | F12: 5.24 | G12: 45939 | H12: 4.14 | I12: =IF(ISNUMBER(H12),(F12-H12)*100,"n/a") -> 110 | J12: Duration choice
B13: 30Y Treasury yield | C13: US Treasury par yield curve | D13: % | E13: 46304 | F13: 5.6 | G13: 45939 | H13: 4.72 | I13: =IF(ISNUMBER(H13),(F13-H13)*100,"n/a") -> 88 | J13: Duration choice: extra yield for long bonds
B14: 2s10s spread (10Y - 2Y) | C14: Formula | D14: % | E14: =E12 -> 46304 | F14: =F12-F11 -> 0.44 | G14: =G12 -> 45939 | H14: =H12-H11 -> 0.54 | I14: =IF(ISNUMBER(H14),(F14-H14)*100,"n/a") -> -10 | J14: Curve shape
B15: Credit
B16: US investment grade OAS | C16: FRED BAMLC0A0CM (ICE BofA) | D16: % | E16: 46303 | F16: 0.82 | G16: 45938 | H16: 0.75 | I16: =IF(ISNUMBER(H16),(F16-H16)*100,"n/a") -> 7 | J16: VCIT: how much credit pays for its risk
B17: US high yield OAS | C17: FRED BAMLH0A0HYM2 (ICE BofA) | D17: % | E17: 46303 | F17: 3.15 | G17: 45938 | H17: 2.84 | I17: =IF(ISNUMBER(H17),(F17-H17)*100,"n/a") -> 31 | J17: HY, if included
B18: Risk and currency
B19: VIX | C19: FRED VIXCLS | D19: index | E19: 46303 | F19: 15.41 | G19: n/a | H19: n/a | I19: n/a | J19: Market stress today
B20: Broad US dollar index | C20: FRED DTWEXBGS | D20: index (Jan 2006=100) | E20: 46297 | F20: 121.3848 | G20: n/a | H20: n/a | I20: n/a | J20: Gold, commodities, non-US equities in USD
B22: Sources: FRED, Federal Reserve Bank of St. Louis (fred.stlouisfed.org); U.S. Department of the Treasury, Daily Treasury Par Yield Curve Rates. Retrieved 12 Oct 2026.
B23: ICE BofA spread data: copyrighted, internal use only (FRED series notes). Cite the source; do not redistribute the series.
B24: Values transcribed automatically from the source pages: spot-check against FRED before use.

Sheet Macro analysis
B2: Macro outlook: consensus (ECFC) and market pricing
B3: All numbers are formulas linked to "ECFC data" and "Market indicators", except the blue WIRP input (also provided by BBG).
L4: Chart data: US inflation consensus vs 5Y breakeven
B5: A. Where each economy is heading: the four regimes of Class 3 | L5: Quarter | M5: CPI (YoY%) | N5: Core PCE (YoY%) | O5: 5Y breakeven (today)
B6: Regime = direction of growth and inflation (Class 3, Part I). Change measured on year-on-year consensus rates. A change of 0 counts as "up". | L6: Q4 26 | M6: ='ECFC data'!$G$17 -> 3.5 | N6: ='ECFC data'!$G$19 -> 3.3 | O6: ='Market indicators'!$F$8 -> 2.34
B7: Region | C7: Real GDP Q4 26 | D7: Real GDP Q4 27 | E7: Δ GDP (pp) | F7: CPI Q4 26 | G7: CPI Q4 27 | H7: Δ CPI (pp) | I7: Regime, Q4 26 → Q4 27 | J7: Regime in 2026, Q1 26 → Q3 26 | L7: Q1 27 | M7: ='ECFC data'!$H$17 -> 3.2 | N7: ='ECFC data'!$H$19 -> 2.8 | O7: ='Market indicators'!$F$8 -> 2.34
B8: United States | C8: ='ECFC data'!$G$8 -> 2.1 | D8: ='ECFC data'!$K$8 -> 2.1 | E8: =D8-C8 -> 0 | F8: ='ECFC data'!$G$17 -> 3.5 | G8: ='ECFC data'!$K$17 -> 2.1 | H8: =G8-F8 -> -1.4 | I8: =IF(AND(E8>=0,H8>=0),"Overheated",IF(E8>=0,"Goldilocks",IF(H8>=0,"Stagflation","Depression"))) -> Goldilocks | J8: =IF(AND(('ECFC data'!$F$8-'ECFC data'!$D$8)>=0,('ECFC data'!$F$17-'ECFC data'!$D$17)>=0),"Overheated",IF(('ECFC data'!$F$8-'ECFC data'!$D$8)>=0,"Goldilocks",IF(('ECFC data'!$F$17-'ECFC data'!$D$17)>=0,"Stagflation","Depression"))) -> Stagflation | L8: Q2 27 | M8: ='ECFC data'!$I$17 -> 2.2 | N8: ='ECFC data'!$I$19 -> 2.6 | O8: ='Market indicators'!$F$8 -> 2.34
B9: Developed economies | C9: ='ECFC data'!$G$45 -> 1.8 | D9: ='ECFC data'!$K$45 -> 1.9 | E9: =D9-C9 -> 0.1 | F9: ='ECFC data'!$G$46 -> 3.9 | G9: ='ECFC data'!$K$46 -> 2.5 | H9: =G9-F9 -> -1.4 | I9: =IF(AND(E9>=0,H9>=0),"Overheated",IF(E9>=0,"Goldilocks",IF(H9>=0,"Stagflation","Depression"))) -> Goldilocks | J9: =IF(AND(('ECFC data'!$F$45-'ECFC data'!$D$45)>=0,('ECFC data'!$F$46-'ECFC data'!$D$46)>=0),"Overheated",IF(('ECFC data'!$F$45-'ECFC data'!$D$45)>=0,"Goldilocks",IF(('ECFC data'!$F$46-'ECFC data'!$D$46)>=0,"Stagflation","Depression"))) -> Overheated | L9: Q3 27 | M9: ='ECFC data'!$J$17 -> 2.4 | N9: ='ECFC data'!$J$19 -> 2.5 | O9: ='Market indicators'!$F$8 -> 2.34
B10: European Union | C10: ='ECFC data'!$G$57 -> 1.3 | D10: ='ECFC data'!$K$57 -> 1.6 | E10: =D10-C10 -> 0.3 | F10: ='ECFC data'!$G$58 -> 3.4 | G10: ='ECFC data'!$K$58 -> 2 | H10: =G10-F10 -> -1.4 | I10: =IF(AND(E10>=0,H10>=0),"Overheated",IF(E10>=0,"Goldilocks",IF(H10>=0,"Stagflation","Depression"))) -> Goldilocks | J10: =IF(AND(('ECFC data'!$F$57-'ECFC data'!$D$57)>=0,('ECFC data'!$F$58-'ECFC data'!$D$58)>=0),"Overheated",IF(('ECFC data'!$F$57-'ECFC data'!$D$57)>=0,"Goldilocks",IF(('ECFC data'!$F$58-'ECFC data'!$D$58)>=0,"Stagflation","Depression"))) -> Overheated | L10: Q4 27 | M10: ='ECFC data'!$K$17 -> 2.1 | N10: ='ECFC data'!$K$19 -> 2.4 | O10: ='Market indicators'!$F$8 -> 2.34
B11: Emerging economies | C11: ='ECFC data'!$G$69 -> 3.9 | D11: ='ECFC data'!$K$69 -> 4.4 | E11: =D11-C11 -> 0.5 | F11: ='ECFC data'!$G$70 -> 3.6 | G11: ='ECFC data'!$K$70 -> 2.9 | H11: =G11-F11 -> -0.7 | I11: =IF(AND(E11>=0,H11>=0),"Overheated",IF(E11>=0,"Goldilocks",IF(H11>=0,"Stagflation","Depression"))) -> Goldilocks | J11: =IF(AND(('ECFC data'!$F$69-'ECFC data'!$D$69)>=0,('ECFC data'!$F$70-'ECFC data'!$D$70)>=0),"Overheated",IF(('ECFC data'!$F$69-'ECFC data'!$D$69)>=0,"Goldilocks",IF(('ECFC data'!$F$70-'ECFC data'!$D$70)>=0,"Stagflation","Depression"))) -> Stagflation | L11: Q1 28 | M11: ='ECFC data'!$L$17 -> 2.3 | N11: ='ECFC data'!$L$19 -> 2.3 | O11: ='Market indicators'!$F$8 -> 2.34
B14: B. United States: what economists expect vs what markets price
B15: Variable | C15: Economists (ECFC) | D15: Horizon of the forecast | E15: Market today | F15: Market measure | G15: Gap, economists − market (bp) | H15: Reading
B16: Fed policy rate | C16: ='ECFC data'!$L$35 -> 3.85 | D16: Q1 28 | E16: =WIRP!G21 -> 4.835 | F16: WIRP implied upper bound, Jan 2028 | G16: =(C16-E16)*100 -> -98.5 | H16: Economists see cuts in 2027-28; the market prices ~3.4 more hikes, peaking in late 2027. Roughly 100bp apart: genuine uncertainty on the rate path
B17: 2Y Treasury yield | C17: ='ECFC data'!$K$37 -> 4.08 | D17: Q4 27 | E17: ='Market indicators'!$F$11 -> 4.8 | F17: 2Y yield, 9 Oct 2026 | G17: =(C17-E17)*100 -> -72 | H17: Economists expect front-end yields to fall
B18: 10Y Treasury yield | C18: ='ECFC data'!$K$38 -> 4.6 | D18: Q4 27 | E18: ='Market indicators'!$F$12 -> 5.24 | F18: 10Y yield, 9 Oct 2026 | G18: =(C18-E18)*100 -> -64 | H18: Economists expect long yields to fall: upside for duration if they are right
B19: Inflation, next 4 quarters | C19: =AVERAGE('ECFC data'!$G$17:$J$17) -> 2.825 | D19: avg Q4 26 – Q3 27 (CPI) | E19: ='Market indicators'!$F$8 -> 2.34 | F19: 5Y breakeven | G19: =(C19-E19)*100 -> 48.5 | H19: Near-term CPI consensus above breakeven; breakeven covers 5 years, so compare with care
B20: Inflation, end of horizon | C20: ='ECFC data'!$L$17 -> 2.3 | D20: Q1 28 (CPI) | E20: ='Market indicators'!$F$8 -> 2.34 | F20: 5Y breakeven | G20: =(C20-E20)*100 -> -4 | H20: By 2028 economists see CPI back near 2.3%: in line with what the market prices
B22: Market rate: WIRP implied effective rate for Jan 2028 plus today's target − effective spread, so it is comparable with the ECFC target-rate forecast.
B24: C. Other consensus signals relevant to the portfolio
B25: Signal | C25: Value | D25: Unit / horizon | H25: Implication for the SAA
B26: US budget balance | C26: ='ECFC data'!$K$32 -> -6.6 | D26: % of GDP, Q4 27 | H26: Persistent deficits (~6.5% of GDP) and debt above 100%: risk of a higher term premium on long bonds. Supports medium rather than long duration
B27: US government debt | C27: ='ECFC data'!$K$33 -> 105 | D27: % of GDP, Q4 27
B28: US core PCE inflation | C28: ='ECFC data'!$G$19 -> 3.3 | D28: % YoY, Q4 26 | H28: Core inflation above 3% until early 2027: the Fed’s hikes are about inflation, not overheating growth
B29: US unemployment | C29: ='ECFC data'!$K$26 -> 4.2 | D29: %, Q4 27 | H29: Labour market stable around 4.2%; payroll growth slow (~60k a month)
B30: US payrolls | C30: ='ECFC data'!$K$27 -> 60 | D30: 000s per month, Q4 27
B31: EUR/USD, expected change | C31: ='ECFC data'!$K$40/'ECFC data'!$F$40-1 -> 0.03539823 | D31: % change, Q3 26 → Q4 27 | H31: Mild dollar weakening expected: small tailwind for non-US equities and gold measured in USD
B32: EM central bank rate, expected change | C32: =('ECFC data'!$L$75-'ECFC data'!$F$75)*100 -> -139 | D32: bp, Q3 26 → Q1 28 | H32: EM central banks expected to ease by about 140bp while EM growth rises to ~4.4%: supportive for EM equities
B33: EU real GDP growth | C33: ='ECFC data'!$K$57 -> 1.6 | D33: % YoY, Q4 27 | H33: Europe grows slowly (~1.5%) with ECB rates near 2.7-2.9%: no case for a European overweight from growth alone
B35: D. Takeaways for the outlook slides
B36: 1. In 2026 inflation rose everywhere. In the US and EM growth slowed at the same time (stagflation: US CPI 2.7% → 3.4%), which explains the Fed hike in September.
B37: 2. The consensus expects a return to goldilocks in 2027 in every region: steady or rising growth, inflation falling back towards 2-2.5%.
B38: 3. Markets do not share that view: fed funds futures price ~3.4 more hikes, to ~4.8% (upper bound) by late 2027; economists see ~3.9% by early 2028.
B39: 4. Economists expect 10Y yields ~60bp lower by end-2027; deficits above 6% of GDP argue the other way for the long end. Medium duration balances the two.
B40: 5. Inflation protection is not expensive: the 5Y breakeven (~2.3%) sits below near-term CPI forecasts and in line with the 2028 consensus.
B41: 6. Conclusion for the SAA: the scenarios are genuinely uncertain (stagflation now, goldilocks expected, hikes priced). We balance risk across regimes instead of betting on one.
L42: Quadrants: right = growth up, left = growth down; top = inflation up, bottom = inflation down. Bottom-right = goldilocks.
B43: Notes: the "European Union" export is the EU-27 aggregate, not the euro area (Eurozone). EM 2Y/10Y consensus series show breaks (aggregate composition changes) and are not used.
B44: Sources: Bloomberg ECFC (consensus of economists), Bloomberg WIRP, FRED, U.S. Treasury.

Sheet WIRP
B2: Fed funds path priced by the market (Bloomberg WIRP, fed funds futures)
B4: Pricing date | C4: 46307
B5: Target rate (upper bound, %) | C5: 4
B6: Effective fed funds rate (%) | C6: 3.88
B7: Current implied overnight rate (%) | C7: 3.879
B8: Spread target − effective (%) | C8: =C5-C6 -> 0.12
B10: FOMC meeting | C10: Net implied probability of a 25bps hike | D10: Cumulative # of 25bp moves | E10: Implied change vs today (%) | F10: Implied overnight rate (%) | G10: Implied upper bound (%) | H10: Effective rate today (%)
B11: 46323 | C11: 0.22 | D11: 0.216 | E11: 0.054 | F11: 3.932 | G11: =F11+$C$8 -> 4.052 | H11: =$C$6 -> 3.88
B12: 46365 | C12: 0.86 | D12: 1.086 | E12: 0.272 | F12: 4.15 | G12: =F12+$C$8 -> 4.27 | H12: =$C$6 -> 3.88
B13: 46414 | C13: 0.42 | D13: 1.496 | E13: 0.374 | F13: 4.253 | G13: =F13+$C$8 -> 4.373 | H13: =$C$6 -> 3.88
B14: 46463 | C14: 0.72 | D14: 2.239 | E14: 0.56 | F14: 4.438 | G14: =F14+$C$8 -> 4.558 | H14: =$C$6 -> 3.88
B15: 46505 | C15: 0.4 | D15: 2.636 | E15: 0.659 | F15: 4.537 | G15: =F15+$C$8 -> 4.657 | H15: =$C$6 -> 3.88
B16: 46547 | C16: 0.43 | D16: 3.056 | E16: 0.764 | F16: 4.642 | G16: =F16+$C$8 -> 4.762 | H16: =$C$6 -> 3.88
B17: 46596 | C17: 0.15 | D17: 3.216 | E17: 0.804 | F17: 4.682 | G17: =F17+$C$8 -> 4.802 | H17: =$C$6 -> 3.88
B18: 46645 | C18: 0.16 | D18: 3.374 | E18: 0.843 | F18: 4.722 | G18: =F18+$C$8 -> 4.842 | H18: =$C$6 -> 3.88
B19: 46687 | C19: 0.04 | D19: 3.406 | E19: 0.851 | F19: 4.73 | G19: =F19+$C$8 -> 4.85 | H19: =$C$6 -> 3.88
B20: 46729 | C20: -0.04 | D20: 3.368 | E20: 0.842 | F20: 4.72 | G20: =F20+$C$8 -> 4.84 | H20: =$C$6 -> 3.88
B21: 46778 | C21: -0.02 | D21: 3.346 | E21: 0.836 | F21: 4.715 | G21: =F21+$C$8 -> 4.835 | H21: =$C$6 -> 3.88
B23: Source: Bloomberg WIRP, fed funds futures, priced 12 Oct 2026 (exported by the team). Blue = from the export; black = formula.
B24: Implied rates are for the effective fed funds rate. "Implied upper bound" adds today's target − effective spread, to compare with ECFC, which forecasts the target rate.
B25: Probabilities and rates are market-implied (they include risk premia), not true probabilities. The raw export shows the probability column ×100 (e.g. 2160%); the clean column is used.
J28: * "negative probability" means there is more consensus on a cut than a hike

Sheet ECFC data
B2: Bloomberg ECFC consensus forecasts, quarterly (exported by the team, 12 Oct 2026)
B3: Blue = values from the ECFC export. Q4 25 to Q2 26 are mostly realised data; Q3 26 onward are estimates and forecasts. Blank = no consensus in the export.
B5: United States
B6: Indicator | C6: Q4 25 | D6: Q1 26 | E6: Q2 26 | F6: Q3 26 | G6: Q4 26 | H6: Q1 27 | I6: Q2 27 | J6: Q3 27 | K6: Q4 27 | L6: Q1 28
B7: Economic Activity
B8: Real GDP (YoY%) | C8: 2 | D8: 2.6 | E8: 2.2 | F8: 1.8 | G8: 2.1 | H8: 2.1 | I8: 2.3 | J8: 2.1 | K8: 2.1 | L8: 2.1
B9: Real GDP (QoQ% SAAR) | C9: 0.2 | D9: 2.5 | E9: 2.2 | F9: 2.8 | G9: 2.1 | H9: 2.1 | I9: 2.1 | J9: 2.2 | K9: 2.2 | L9: 2.2
B10: Consumer Spending (QoQ% SAAR) | C10: 1.9 | D10: 0.7 | E10: 3.8 | F10: 2.5 | G10: 1.9 | H10: 1.9 | I10: 2 | J10: 2 | K10: 2.1 | L10: 2.2
B11: Government Spending (QoQ% SAAR) | C11: -5.7 | D11: 4.7 | E11: -0.1 | F11: 1.5 | G11: 1.4 | H11: 1.2 | I11: 1.2 | J11: 1.1 | K11: 1.1 | L11: 1.1
B12: Private Investment (QoQ% SAAR) | C12: 1.1 | D12: 7.2 | E12: 4.6 | F12: 7.4 | G12: 4.4 | H12: 4 | I12: 4 | J12: 3.8 | K12: 3.8 | L12: 3.8
B13: Exports (QoQ% SAAR) | C13: -4.2 | D13: 13.9 | E13: 5 | F13: 2 | G13: 2.7 | H13: 2.5 | I13: 2.7 | J13: 2.8 | K13: 2.7 | L13: 2.8
B14: Imports (QoQ% SAAR) | C14: -1.5 | D14: 11.5 | E14: 12.6 | F14: 7 | G14: 3.5 | H14: 3 | I14: 3 | J14: 3 | K14: 3 | L14: 2.8
B15: Industrial Production (YoY %) | C15: 1.6 | D15: 0.8 | E15: 1.5 | F15: 1.4 | G15: 2.2 | H15: 2.2 | I15: 1.8 | J15: 1.8 | K15: 1.8 | L15: 2
B16: Price Indices
B17: CPI (YoY%) | C17: 2.7 | D17: 2.7 | E17: 3.9 | F17: 3.4 | G17: 3.5 | H17: 3.2 | I17: 2.2 | J17: 2.4 | K17: 2.1 | L17: 2.3
B18: PCE Price Index (YoY%) | C18: 2.8 | D18: 3.1 | E18: 3.9 | F18: 3.7 | G18: 3.6 | H18: 3.1 | I18: 2.3 | J18: 2.3 | K18: 2.2 | L18: 2.1
B19: Core PCE (yoy%) | C19: 2.8 | D19: 3 | E19: 3.1 | F19: 3.3 | G19: 3.3 | H19: 2.8 | I19: 2.6 | J19: 2.5 | K19: 2.4 | L19: 2.3
B20: Housing Market
B21: Housing Starts (000s SAAR, monthly avg.) | C21: 1323 | D21: 1418 | E21: 1345 | F21: 1326 | G21: 1326 | H21: 1327 | I21: 1331 | J21: 1349 | K21: 1363 | L21: 1368
B22: New Home Sales (000s SAAR, monthly avg.) | C22: 711 | D22: 622 | E22: 650 | F22: 628 | G22: 632 | H22: 647 | I22: 653 | J22: 664 | K22: 676 | L22: 694
B23: Existing Home Sales (Mln SAAR, monthly avg.) | C23: 4.2 | D23: 4.1 | E23: 4.1 | F23: 4 | G23: 4.1 | H23: 4.1 | I23: 4.2 | J23: 4.2 | K23: 4.2 | L23: 4.3
B24: Building Permits (000s SAAR, monthly avg.) | C24: 1438 | D24: 1432 | E24: 1402 | F24: 1416 | G24: 1406 | H24: 1405 | I24: 1410 | J24: 1424 | K24: 1437 | L24: 1418
B25: Labor Market
B26: Unemployment (%) | C26: 4.5 | D26: 4.3 | E26: 4.3 | F26: 4.1 | G26: 4.2 | H26: 4.2 | I26: 4.2 | J26: 4.2 | K26: 4.2 | L26: 4.2
B27: Non Farm Payrolls (000s SA, monthly chg.) | C27: -39 | D27: 73 | E27: 81 | F27: 51 | G27: 65 | H27: 60 | I27: 60 | J27: 60 | K27: 60 | L27: 71
B28: Average Hourly Earnings (YoY%) | C28: 3.9 | D28: 3.6 | E28: 3.4 | F28: 3.1 | G28: 3.1 | H28: 3.1 | I28: 3.1 | J28: 3.2 | K28: 3.2 | L28: 3.3
B29: External Balance
B30: Curr. Acct. (% of GDP) | C30: -3.7 | D30: -3 | E30: -2.9 | F30: -3.4 | G30: -3.3 | H30: -3.4 | I30: -3.3 | J30: -3.3 | K30: -3.3 | L30: -3.3
B31: Financial Balances
B32: Budget (% of GDP) | C32: -5.3 | D32: -5.1 | E32: -5.5 | F32: -6.2 | G32: -6.4 | H32: -6.6 | I32: -6.5 | J32: -6.5 | K32: -6.6 | L32: -6.6
B33: Government Debt (% of GDP) | E33: 101.7 | F33: 102 | G33: 103 | H33: 104 | I33: 105 | J33: 105 | K33: 105 | L33: 104.8
B34: Interest Rates
B35: Central Bank Rate (%) | C35: 3.75 | D35: 3.75 | E35: 3.75 | F35: 4 | G35: 4.25 | H35: 4.28 | I35: 4.25 | J35: 4.16 | K35: 4.08 | L35: 3.85
B36: 3-Month Rate (%) | C36: 3.65 | D36: 3.68 | E36: 3.73 | F36: 4.08 | G36: 4.13 | H36: 4.15 | I36: 4.12 | J36: 4.04 | K36: 3.99 | L36: 3.83
B37: 2-Year Note (%) | C37: 3.48 | D37: 3.8 | E37: 4.18 | F37: 4.89 | G37: 4.46 | H37: 4.38 | I37: 4.28 | J37: 4.19 | K37: 4.08 | L37: 3.99
B38: 10-Year Note (%) | C38: 4.17 | D38: 4.32 | E38: 4.47 | F38: 5.29 | G38: 4.87 | H38: 4.8 | I38: 4.72 | J38: 4.65 | K38: 4.6 | L38: 4.52
B39: Exchange Rates
B40: EURUSD | C40: 1.17 | D40: 1.16 | E40: 1.14 | F40: 1.13 | G40: 1.14 | H40: 1.14 | I40: 1.15 | J40: 1.16 | K40: 1.17
B42: Developed economies
B43: Indicator | C43: Q4 25 | D43: Q1 26 | E43: Q2 26 | F43: Q3 26 | G43: Q4 26 | H43: Q1 27 | I43: Q2 27 | J43: Q3 27 | K43: Q4 27 | L43: Q1 28
...

Sheet Yield curve
B2: US Treasury par yield curve (%)
B3: All numbers are formulas linked to "ECFC data" and "Market indicators", except the blue WIRP input (also provided by BBG).
B4: Maturity | C4: 9 Oct 2026 | D4: 9 Oct 2025 | E4: Change (bp)
B5: 1M | C5: 0.0413 | D5: 0.042 | E5: =(C5-D5)*10000 -> -7
B6: 3M | C6: 0.0425 | D6: 0.0403 | E6: =(C6-D6)*10000 -> 22
B7: 6M | C7: 0.0432 | D7: 0.0383 | E7: =(C7-D7)*10000 -> 49
B8: 1Y | C8: 0.0447 | D8: 0.0366 | E8: =(C8-D8)*10000 -> 81 | J8: =IF(AND(('ECFC data'!$F$8-'ECFC data'!$D$8)>=0,('ECFC data'!$F$17-'ECFC data'!$D$17)>=0),"Overheated",IF(('ECFC data'!$F$8-'ECFC data'!$D$8)>=0,"Goldilocks",IF(('ECFC data'!$F$17-'ECFC data'!$D$17)>=0,"Stagflation","Depression"))) -> Stagflation
B9: 2Y | C9: 0.048 | D9: 0.036 | E9: =(C9-D9)*10000 -> 120
B10: 3Y | C10: 0.0489 | D10: 0.0359 | E10: =(C10-D10)*10000 -> 130
B11: 5Y | C11: 0.0502 | D11: 0.0374 | E11: =(C11-D11)*10000 -> 128
B12: 7Y | C12: 0.0513 | D12: 0.0392 | E12: =(C12-D12)*10000 -> 121
B13: 10Y | C13: 0.0524 | D13: 0.0414 | E13: =(C13-D13)*10000 -> 110
B14: 20Y | C14: 0.0565 | D14: 0.047 | E14: =(C14-D14)*10000 -> 95
B15: 30Y | C15: 0.056 | D15: 0.0472 | E15: =(C15-D15)*10000 -> 88
C16: ='ECFC data'!$L$35 -> 3.85
B17: Source: U.S. Department of the Treasury, Daily Treasury Par Yield Curve Rates (home.treasury.gov). Retrieved 12 Oct 2026.
B18: Blue cells are hardcoded inputs copied from the source; check against the Treasury table before use.
